[2020-03-23 17:48:02,672] [ERROR] [app.py -- log_exception:1891] [Exception on /v1/token [POST]]
Traceback (most recent call last):
  File "D:\a_yunjia_project\shnaghai_project\shanghai_env\lib\site-packages\flask\app.py", line 1949, in full_dispatch_request
    rv = self.dispatch_request()
  File "D:\a_yunjia_project\shnaghai_project\shanghai_env\lib\site-packages\flask\app.py", line 1935, in dispatch_request
    return self.view_functions[rule.endpoint](**req.view_args)
  File "D:\a_a_a_project\AI_Speech_QIA\src\app\api\sysmng\token.py", line 20, in token_get
    form = LoginForm().validate_for_api()
  File "D:\a_a_a_project\AI_Speech_QIA\src\app\validators\base.py", line 27, in validate_for_api
    raise ParameterException(msg=self.errors.values())
app.libs.error_code.ParameterException: 400 Bad Request: dict_values([['账号：不允许为空']])

During handling of the above exception, another exception occurred:

Traceback (most recent call last):
  File "D:\a_yunjia_project\shnaghai_project\shanghai_env\lib\site-packages\flask\app.py", line 2446, in wsgi_app
    response = self.full_dispatch_request()
  File "D:\a_yunjia_project\shnaghai_project\shanghai_env\lib\site-packages\flask\app.py", line 1951, in full_dispatch_request
    rv = self.handle_user_exception(e)
  File "D:\a_yunjia_project\shnaghai_project\shanghai_env\lib\site-packages\flask_cors\extension.py", line 161, in wrapped_function
    return cors_after_request(app.make_response(f(*args, **kwargs)))
  File "D:\a_yunjia_project\shnaghai_project\shanghai_env\lib\site-packages\flask\app.py", line 2116, in make_response
    rv = self.response_class.force_type(rv, request.environ)
  File "D:\a_yunjia_project\shnaghai_project\shanghai_env\lib\site-packages\werkzeug\wrappers\base_response.py", line 269, in force_type
    response = BaseResponse(*_run_wsgi_app(response, environ))
  File "D:\a_yunjia_project\shnaghai_project\shanghai_env\lib\site-packages\werkzeug\test.py", line 1119, in run_wsgi_app
    app_rv = app(environ, start_response)
  File "D:\a_yunjia_project\shnaghai_project\shanghai_env\lib\site-packages\werkzeug\exceptions.py", line 191, in __call__
    response = self.get_response(environ)
  File "D:\a_yunjia_project\shnaghai_project\shanghai_env\lib\site-packages\werkzeug\exceptions.py", line 182, in get_response
    return Response(self.get_body(environ), self.code, headers)
  File "D:\a_a_a_project\AI_Speech_QIA\src\app\libs\error.py", line 32, in get_body
    text = json.dumps(body)
  File "D:\a_yunjia_project\shnaghai_project\shanghai_env\lib\site-packages\flask\json\__init__.py", line 211, in dumps
    rv = _json.dumps(obj, **kwargs)
  File "D:\job_soft\python37\Lib\json\__init__.py", line 238, in dumps
    **kw).encode(obj)
  File "D:\job_soft\python37\Lib\json\encoder.py", line 199, in encode
    chunks = self.iterencode(o, _one_shot=True)
  File "D:\job_soft\python37\Lib\json\encoder.py", line 257, in iterencode
    return _iterencode(o, 0)
  File "D:\a_a_a_project\AI_Speech_QIA\src\app\app.py", line 19, in default
    raise ServerError()
app.libs.error_code.ServerError: 500 Internal Server Error: None
